[2024-01-31 05:26:50,976] {taskinstance.py:1159} INFO - Dependencies all met for <TaskInstance: database_connection_testing_mysql_postgres_1.postgres_conn_check scheduled__2024-01-30T05:26:24.024529+00:00 [queued]>
[2024-01-31 05:26:50,983] {taskinstance.py:1159} INFO - Dependencies all met for <TaskInstance: database_connection_testing_mysql_postgres_1.postgres_conn_check scheduled__2024-01-30T05:26:24.024529+00:00 [queued]>
[2024-01-31 05:26:50,983] {taskinstance.py:1356} INFO - 
--------------------------------------------------------------------------------
[2024-01-31 05:26:50,983] {taskinstance.py:1357} INFO - Starting attempt 1 of 2
[2024-01-31 05:26:50,983] {taskinstance.py:1358} INFO - 
--------------------------------------------------------------------------------
[2024-01-31 05:26:50,992] {taskinstance.py:1377} INFO - Executing <Task(PythonOperator): postgres_conn_check> on 2024-01-30 05:26:24.024529+00:00
[2024-01-31 05:26:50,995] {standard_task_runner.py:52} INFO - Started process 269 to run task
[2024-01-31 05:26:51,003] {standard_task_runner.py:79} INFO - Running: ['***', 'tasks', 'run', 'database_connection_testing_mysql_postgres_1', 'postgres_conn_check', 'scheduled__2024-01-30T05:26:24.024529+00:00', '--job-id', '3', '--raw', '--subdir', 'DAGS_FOLDER/test_connection.py', '--cfg-path', '/tmp/tmpf1y44itb', '--error-file', '/tmp/tmpw3oq8ral']
[2024-01-31 05:26:51,007] {standard_task_runner.py:80} INFO - Job 3: Subtask postgres_conn_check
[2024-01-31 05:26:51,126] {task_command.py:369} INFO - Running <TaskInstance: database_connection_testing_mysql_postgres_1.postgres_conn_check scheduled__2024-01-30T05:26:24.024529+00:00 [running]> on host f72468368ef9
[2024-01-31 05:26:51,267] {taskinstance.py:1571} INFO - Exporting the following env vars:
AIRFLOW_CTX_DAG_OWNER=***
AIRFLOW_CTX_DAG_ID=database_connection_testing_mysql_postgres_1
AIRFLOW_CTX_TASK_ID=postgres_conn_check
AIRFLOW_CTX_EXECUTION_DATE=2024-01-30T05:26:24.024529+00:00
AIRFLOW_CTX_TRY_NUMBER=1
AIRFLOW_CTX_DAG_RUN_ID=scheduled__2024-01-30T05:26:24.024529+00:00
[2024-01-31 05:28:06,364] {timeout.py:67} ERROR - Process timed out, PID: 269
[2024-01-31 05:28:06,390] {logging_mixin.py:115} INFO - Error connecting to PostgreSQL: Timeout, PID: 269
[2024-01-31 05:28:06,398] {python.py:173} INFO - Done. Returned value was: False
[2024-01-31 05:28:06,526] {taskinstance.py:1400} INFO - Marking task as SUCCESS. dag_id=database_connection_testing_mysql_postgres_1, task_id=postgres_conn_check, execution_date=20240130T052624, start_date=20240131T052650, end_date=20240131T052806
[2024-01-31 05:28:06,568] {local_task_job.py:156} INFO - Task exited with return code 0
[2024-01-31 05:28:06,622] {local_task_job.py:273} INFO - 1 downstream tasks scheduled from follow-on schedule check
