[2024-02-01 16:01:58,738] {taskinstance.py:1159} INFO - Dependencies all met for <TaskInstance: project_6_18.dim_mysql scheduled__2024-01-31T16:01:30.999522+00:00 [queued]>
[2024-02-01 16:01:58,765] {taskinstance.py:1159} INFO - Dependencies all met for <TaskInstance: project_6_18.dim_mysql scheduled__2024-01-31T16:01:30.999522+00:00 [queued]>
[2024-02-01 16:01:58,766] {taskinstance.py:1356} INFO - 
--------------------------------------------------------------------------------
[2024-02-01 16:01:58,766] {taskinstance.py:1357} INFO - Starting attempt 1 of 2
[2024-02-01 16:01:58,766] {taskinstance.py:1358} INFO - 
--------------------------------------------------------------------------------
[2024-02-01 16:01:58,803] {taskinstance.py:1377} INFO - Executing <Task(MySqlOperator): dim_mysql> on 2024-01-31 16:01:30.999522+00:00
[2024-02-01 16:01:58,813] {standard_task_runner.py:52} INFO - Started process 6264 to run task
[2024-02-01 16:01:58,819] {standard_task_runner.py:79} INFO - Running: ['***', 'tasks', 'run', 'project_6_18', 'dim_mysql', 'scheduled__2024-01-31T16:01:30.999522+00:00', '--job-id', '249', '--raw', '--subdir', 'DAGS_FOLDER/main.py', '--cfg-path', '/tmp/tmpbwhybtte', '--error-file', '/tmp/tmpnccxfifo']
[2024-02-01 16:01:58,820] {standard_task_runner.py:80} INFO - Job 249: Subtask dim_mysql
[2024-02-01 16:01:59,112] {task_command.py:369} INFO - Running <TaskInstance: project_6_18.dim_mysql scheduled__2024-01-31T16:01:30.999522+00:00 [running]> on host 1fafaef2f352
[2024-02-01 16:01:59,436] {taskinstance.py:1571} INFO - Exporting the following env vars:
AIRFLOW_CTX_DAG_OWNER=***
AIRFLOW_CTX_DAG_ID=project_6_18
AIRFLOW_CTX_TASK_ID=dim_mysql
AIRFLOW_CTX_EXECUTION_DATE=2024-01-31T16:01:30.999522+00:00
AIRFLOW_CTX_TRY_NUMBER=1
AIRFLOW_CTX_DAG_RUN_ID=scheduled__2024-01-31T16:01:30.999522+00:00
[2024-02-01 16:01:59,437] {mysql.py:82} INFO - Executing: CREATE TABLE IF NOT EXISTS case_table (
    id INT PRIMARY KEY,
    status_name VARCHAR(255) NOT NULL,
    status_detail VARCHAR(255) NOT NULL
);

CREATE TABLE IF NOT EXISTS district_table (
    district_id INT PRIMARY KEY,
    province_id INT,
    district_name VARCHAR(255) NOT NULL,
    FOREIGN KEY (province_id) REFERENCES province_table(province_id)
);

CREATE TABLE IF NOT EXISTS province_table (
    province_id INT PRIMARY KEY,
    province_name VARCHAR(255) NOT NULL
);
[2024-02-01 16:01:59,535] {base.py:68} INFO - Using connection ID 'mysql_data_staging' for task execution.
[2024-02-01 16:01:59,714] {dbapi.py:208} INFO - Running statement: CREATE TABLE IF NOT EXISTS case_table (
    id INT PRIMARY KEY,
    status_name VARCHAR(255) NOT NULL,
    status_detail VARCHAR(255) NOT NULL
);

CREATE TABLE IF NOT EXISTS district_table (
    district_id INT PRIMARY KEY,
    province_id INT,
    district_name VARCHAR(255) NOT NULL,
    FOREIGN KEY (province_id) REFERENCES province_table(province_id)
);

CREATE TABLE IF NOT EXISTS province_table (
    province_id INT PRIMARY KEY,
    province_name VARCHAR(255) NOT NULL
);, parameters: None
[2024-02-01 16:01:59,741] {dbapi.py:216} INFO - Rows affected: 0
[2024-02-01 16:01:59,749] {taskinstance.py:1889} ERROR - Task failed with exception
Traceback (most recent call last):
  File "/home/airflow/.local/lib/python3.7/site-packages/airflow/providers/mysql/operators/mysql.py", line 84, in execute
    hook.run(self.sql, autocommit=self.autocommit, parameters=self.parameters)
  File "/home/airflow/.local/lib/python3.7/site-packages/airflow/hooks/dbapi.py", line 191, in run
    results.append(result)
  File "/usr/local/lib/python3.7/contextlib.py", line 298, in __exit__
    self.thing.close()
  File "/home/airflow/.local/lib/python3.7/site-packages/MySQLdb/cursors.py", line 83, in close
    while self.nextset():
  File "/home/airflow/.local/lib/python3.7/site-packages/MySQLdb/cursors.py", line 137, in nextset
    nr = db.next_result()
MySQLdb._exceptions.OperationalError: (1824, "Failed to open the referenced table 'province_table'")
[2024-02-01 16:01:59,830] {taskinstance.py:1400} INFO - Marking task as UP_FOR_RETRY. dag_id=project_6_18, task_id=dim_mysql, execution_date=20240131T160130, start_date=20240201T160158, end_date=20240201T160159
[2024-02-01 16:01:59,871] {standard_task_runner.py:97} ERROR - Failed to execute job 249 for task dim_mysql ((1824, "Failed to open the referenced table 'province_table'"); 6264)
[2024-02-01 16:01:59,923] {local_task_job.py:156} INFO - Task exited with return code 1
[2024-02-01 16:02:00,200] {local_task_job.py:273} INFO - 0 downstream tasks scheduled from follow-on schedule check
