[2024-02-01 17:47:19,104] {taskinstance.py:1159} INFO - Dependencies all met for <TaskInstance: project_6_23.dim_table_creation manual__2024-02-01T17:46:53.127611+00:00 [queued]>
[2024-02-01 17:47:19,139] {taskinstance.py:1159} INFO - Dependencies all met for <TaskInstance: project_6_23.dim_table_creation manual__2024-02-01T17:46:53.127611+00:00 [queued]>
[2024-02-01 17:47:19,140] {taskinstance.py:1356} INFO - 
--------------------------------------------------------------------------------
[2024-02-01 17:47:19,140] {taskinstance.py:1357} INFO - Starting attempt 1 of 2
[2024-02-01 17:47:19,140] {taskinstance.py:1358} INFO - 
--------------------------------------------------------------------------------
[2024-02-01 17:47:19,191] {taskinstance.py:1377} INFO - Executing <Task(PythonOperator): dim_table_creation> on 2024-02-01 17:46:53.127611+00:00
[2024-02-01 17:47:19,248] {standard_task_runner.py:52} INFO - Started process 10041 to run task
[2024-02-01 17:47:19,255] {standard_task_runner.py:79} INFO - Running: ['***', 'tasks', 'run', 'project_6_23', 'dim_table_creation', 'manual__2024-02-01T17:46:53.127611+00:00', '--job-id', '363', '--raw', '--subdir', 'DAGS_FOLDER/main.py', '--cfg-path', '/tmp/tmpqq0fkk4_', '--error-file', '/tmp/tmpeve9ggx7']
[2024-02-01 17:47:19,257] {standard_task_runner.py:80} INFO - Job 363: Subtask dim_table_creation
[2024-02-01 17:47:19,617] {task_command.py:369} INFO - Running <TaskInstance: project_6_23.dim_table_creation manual__2024-02-01T17:46:53.127611+00:00 [running]> on host 1fafaef2f352
[2024-02-01 17:47:20,006] {taskinstance.py:1571} INFO - Exporting the following env vars:
AIRFLOW_CTX_DAG_OWNER=***
AIRFLOW_CTX_DAG_ID=project_6_23
AIRFLOW_CTX_TASK_ID=dim_table_creation
AIRFLOW_CTX_EXECUTION_DATE=2024-02-01T17:46:53.127611+00:00
AIRFLOW_CTX_TRY_NUMBER=1
AIRFLOW_CTX_DAG_RUN_ID=manual__2024-02-01T17:46:53.127611+00:00
[2024-02-01 17:47:20,109] {logging_mixin.py:115} INFO -    kode_prov   nama_prov
0         32  Jawa Barat
[2024-02-01 17:47:20,119] {logging_mixin.py:115} INFO -    kode_kab  kode_prov         nama_kab
0      3201         32  Kabupaten Bogor
[2024-02-01 17:47:20,134] {logging_mixin.py:115} INFO -    case_id   status_name             status_detail
0        1  closecontact  closecontact_dikarantina
1        2  closecontact    closecontact_discarded
2        3  closecontact    closecontact_meninggal
3        4      probable        probable_diisolasi
4        5      probable        probable_discarded
[2024-02-01 17:47:20,207] {logging_mixin.py:115} INFO - Connect PostgreSQL using psycopg2
[2024-02-01 17:47:20,270] {logging_mixin.py:115} INFO - Connect Engine MySQL
[2024-02-01 17:47:20,367] {taskinstance.py:1889} ERROR - Task failed with exception
Traceback (most recent call last):
  File "/home/airflow/.local/lib/python3.7/site-packages/mysql/connector/connection_cext.py", line 538, in cmd_query
    query_attrs=self._query_attrs)
_mysql_connector.MySQLInterfaceError: Duplicate entry '1' for key 'case_table.PRIMARY'

During handling of the above exception, another exception occurred:

Traceback (most recent call last):
  File "/home/airflow/.local/lib/python3.7/site-packages/sqlalchemy/engine/base.py", line 1706, in _execute_context
    cursor, statement, parameters, context
  File "/home/airflow/.local/lib/python3.7/site-packages/sqlalchemy/engine/default.py", line 716, in do_execute
    cursor.execute(statement, parameters)
  File "/home/airflow/.local/lib/python3.7/site-packages/mysql/connector/cursor_cext.py", line 271, in execute
    raw_as_string=self._raw_as_string)
  File "/home/airflow/.local/lib/python3.7/site-packages/mysql/connector/connection_cext.py", line 541, in cmd_query
    sqlstate=exc.sqlstate)
mysql.connector.errors.IntegrityError: 1062 (23000): Duplicate entry '1' for key 'case_table.PRIMARY'

The above exception was the direct cause of the following exception:

Traceback (most recent call last):
  File "/home/airflow/.local/lib/python3.7/site-packages/airflow/operators/python.py", line 171, in execute
    return_value = self.execute_callable()
  File "/home/airflow/.local/lib/python3.7/site-packages/airflow/operators/python.py", line 189, in execute_callable
    return self.python_callable(*self.op_args, **self.op_kwargs)
  File "/opt/airflow/dags/main.py", line 155, in dim_table_creation
    insert_into_mysql(engine_mysql, 'case_table', df_split)
  File "/opt/airflow/dags/main.py", line 108, in insert_into_mysql
    conn.execute(f"INSERT INTO {table_name} VALUES {tuple(row)}")
  File "/home/airflow/.local/lib/python3.7/site-packages/sqlalchemy/engine/base.py", line 1190, in execute
    future=False,
  File "/home/airflow/.local/lib/python3.7/site-packages/sqlalchemy/engine/base.py", line 1491, in _exec_driver_sql
    distilled_parameters,
  File "/home/airflow/.local/lib/python3.7/site-packages/sqlalchemy/engine/base.py", line 1749, in _execute_context
    e, statement, parameters, cursor, context
  File "/home/airflow/.local/lib/python3.7/site-packages/sqlalchemy/engine/base.py", line 1930, in _handle_dbapi_exception
    sqlalchemy_exception, with_traceback=exc_info[2], from_=e
  File "/home/airflow/.local/lib/python3.7/site-packages/sqlalchemy/util/compat.py", line 211, in raise_
    raise exception
  File "/home/airflow/.local/lib/python3.7/site-packages/sqlalchemy/engine/base.py", line 1706, in _execute_context
    cursor, statement, parameters, context
  File "/home/airflow/.local/lib/python3.7/site-packages/sqlalchemy/engine/default.py", line 716, in do_execute
    cursor.execute(statement, parameters)
  File "/home/airflow/.local/lib/python3.7/site-packages/mysql/connector/cursor_cext.py", line 271, in execute
    raw_as_string=self._raw_as_string)
  File "/home/airflow/.local/lib/python3.7/site-packages/mysql/connector/connection_cext.py", line 541, in cmd_query
    sqlstate=exc.sqlstate)
sqlalchemy.exc.IntegrityError: (mysql.connector.errors.IntegrityError) 1062 (23000): Duplicate entry '1' for key 'case_table.PRIMARY'
[SQL: INSERT INTO case_table VALUES (1, 'closecontact', 'closecontact_dikarantina')]
(Background on this error at: http://sqlalche.me/e/14/gkpj)
[2024-02-01 17:47:20,456] {taskinstance.py:1400} INFO - Marking task as UP_FOR_RETRY. dag_id=project_6_23, task_id=dim_table_creation, execution_date=20240201T174653, start_date=20240201T174719, end_date=20240201T174720
[2024-02-01 17:47:20,500] {standard_task_runner.py:97} ERROR - Failed to execute job 363 for task dim_table_creation ((mysql.connector.errors.IntegrityError) 1062 (23000): Duplicate entry '1' for key 'case_table.PRIMARY'
[SQL: INSERT INTO case_table VALUES (1, 'closecontact', 'closecontact_dikarantina')]
(Background on this error at: http://sqlalche.me/e/14/gkpj); 10041)
[2024-02-01 17:47:20,519] {local_task_job.py:156} INFO - Task exited with return code 1
[2024-02-01 17:47:20,763] {local_task_job.py:273} INFO - 0 downstream tasks scheduled from follow-on schedule check
