[2024-01-31 05:26:51,000] {taskinstance.py:1159} INFO - Dependencies all met for <TaskInstance: database_connection_testing_mysql_postgres_1.postgres_conn_check manual__2024-01-31T05:26:49.015398+00:00 [queued]>
[2024-01-31 05:26:51,009] {taskinstance.py:1159} INFO - Dependencies all met for <TaskInstance: database_connection_testing_mysql_postgres_1.postgres_conn_check manual__2024-01-31T05:26:49.015398+00:00 [queued]>
[2024-01-31 05:26:51,009] {taskinstance.py:1356} INFO - 
--------------------------------------------------------------------------------
[2024-01-31 05:26:51,010] {taskinstance.py:1357} INFO - Starting attempt 1 of 2
[2024-01-31 05:26:51,010] {taskinstance.py:1358} INFO - 
--------------------------------------------------------------------------------
[2024-01-31 05:26:51,021] {taskinstance.py:1377} INFO - Executing <Task(PythonOperator): postgres_conn_check> on 2024-01-31 05:26:49.015398+00:00
[2024-01-31 05:26:51,025] {standard_task_runner.py:52} INFO - Started process 270 to run task
[2024-01-31 05:26:51,047] {standard_task_runner.py:79} INFO - Running: ['***', 'tasks', 'run', 'database_connection_testing_mysql_postgres_1', 'postgres_conn_check', 'manual__2024-01-31T05:26:49.015398+00:00', '--job-id', '2', '--raw', '--subdir', 'DAGS_FOLDER/test_connection.py', '--cfg-path', '/tmp/tmpfesdir11', '--error-file', '/tmp/tmpx219cl2j']
[2024-01-31 05:26:51,051] {standard_task_runner.py:80} INFO - Job 2: Subtask postgres_conn_check
[2024-01-31 05:26:51,150] {task_command.py:369} INFO - Running <TaskInstance: database_connection_testing_mysql_postgres_1.postgres_conn_check manual__2024-01-31T05:26:49.015398+00:00 [running]> on host f72468368ef9
[2024-01-31 05:26:51,279] {taskinstance.py:1571} INFO - Exporting the following env vars:
AIRFLOW_CTX_DAG_OWNER=***
AIRFLOW_CTX_DAG_ID=database_connection_testing_mysql_postgres_1
AIRFLOW_CTX_TASK_ID=postgres_conn_check
AIRFLOW_CTX_EXECUTION_DATE=2024-01-31T05:26:49.015398+00:00
AIRFLOW_CTX_TRY_NUMBER=1
AIRFLOW_CTX_DAG_RUN_ID=manual__2024-01-31T05:26:49.015398+00:00
[2024-01-31 05:28:06,375] {timeout.py:67} ERROR - Process timed out, PID: 270
[2024-01-31 05:28:06,397] {logging_mixin.py:115} INFO - Error connecting to PostgreSQL: Timeout, PID: 270
[2024-01-31 05:28:06,398] {python.py:173} INFO - Done. Returned value was: False
[2024-01-31 05:28:06,526] {taskinstance.py:1400} INFO - Marking task as SUCCESS. dag_id=database_connection_testing_mysql_postgres_1, task_id=postgres_conn_check, execution_date=20240131T052649, start_date=20240131T052651, end_date=20240131T052806
[2024-01-31 05:28:06,568] {local_task_job.py:156} INFO - Task exited with return code 0
[2024-01-31 05:28:06,623] {local_task_job.py:273} INFO - 1 downstream tasks scheduled from follow-on schedule check
