[2024-01-31 15:38:04,639] {taskinstance.py:1159} INFO - Dependencies all met for <TaskInstance: project_6_9.api_url_request manual__2024-01-31T15:38:01.809045+00:00 [queued]>
[2024-01-31 15:38:04,657] {taskinstance.py:1159} INFO - Dependencies all met for <TaskInstance: project_6_9.api_url_request manual__2024-01-31T15:38:01.809045+00:00 [queued]>
[2024-01-31 15:38:04,658] {taskinstance.py:1356} INFO - 
--------------------------------------------------------------------------------
[2024-01-31 15:38:04,658] {taskinstance.py:1357} INFO - Starting attempt 1 of 2
[2024-01-31 15:38:04,658] {taskinstance.py:1358} INFO - 
--------------------------------------------------------------------------------
[2024-01-31 15:38:04,687] {taskinstance.py:1377} INFO - Executing <Task(PythonOperator): api_url_request> on 2024-01-31 15:38:01.809045+00:00
[2024-01-31 15:38:04,712] {standard_task_runner.py:52} INFO - Started process 7909 to run task
[2024-01-31 15:38:04,724] {standard_task_runner.py:79} INFO - Running: ['***', 'tasks', 'run', 'project_6_9', 'api_url_request', 'manual__2024-01-31T15:38:01.809045+00:00', '--job-id', '113', '--raw', '--subdir', 'DAGS_FOLDER/main.py', '--cfg-path', '/tmp/tmp9v5qr23x', '--error-file', '/tmp/tmpeqw1yei3']
[2024-01-31 15:38:04,725] {standard_task_runner.py:80} INFO - Job 113: Subtask api_url_request
[2024-01-31 15:38:04,973] {task_command.py:369} INFO - Running <TaskInstance: project_6_9.api_url_request manual__2024-01-31T15:38:01.809045+00:00 [running]> on host 8ebb6ccf62d7
[2024-01-31 15:38:05,393] {taskinstance.py:1571} INFO - Exporting the following env vars:
AIRFLOW_CTX_DAG_OWNER=***
AIRFLOW_CTX_DAG_ID=project_6_9
AIRFLOW_CTX_TASK_ID=api_url_request
AIRFLOW_CTX_EXECUTION_DATE=2024-01-31T15:38:01.809045+00:00
AIRFLOW_CTX_TRY_NUMBER=1
AIRFLOW_CTX_DAG_RUN_ID=manual__2024-01-31T15:38:01.809045+00:00
[2024-01-31 15:38:05,502] {logging_mixin.py:115} INFO - Connect Engine MySQL
[2024-01-31 15:38:05,969] {taskinstance.py:1889} ERROR - Task failed with exception
Traceback (most recent call last):
  File "/home/airflow/.local/lib/python3.7/site-packages/mysql/connector/connection_cext.py", line 538, in cmd_query
    query_attrs=self._query_attrs)
_mysql_connector.MySQLInterfaceError: Unknown table 'mysql-data-staging.raw_covid_data'

During handling of the above exception, another exception occurred:

Traceback (most recent call last):
  File "/home/airflow/.local/lib/python3.7/site-packages/sqlalchemy/engine/base.py", line 1706, in _execute_context
    cursor, statement, parameters, context
  File "/home/airflow/.local/lib/python3.7/site-packages/sqlalchemy/engine/default.py", line 716, in do_execute
    cursor.execute(statement, parameters)
  File "/home/airflow/.local/lib/python3.7/site-packages/mysql/connector/cursor_cext.py", line 271, in execute
    raw_as_string=self._raw_as_string)
  File "/home/airflow/.local/lib/python3.7/site-packages/mysql/connector/connection_cext.py", line 541, in cmd_query
    sqlstate=exc.sqlstate)
mysql.connector.errors.ProgrammingError: 1051 (42S02): Unknown table 'mysql-data-staging.raw_covid_data'

The above exception was the direct cause of the following exception:

Traceback (most recent call last):
  File "/home/airflow/.local/lib/python3.7/site-packages/airflow/operators/python.py", line 171, in execute
    return_value = self.execute_callable()
  File "/home/airflow/.local/lib/python3.7/site-packages/airflow/operators/python.py", line 189, in execute_callable
    return self.python_callable(*self.op_args, **self.op_kwargs)
  File "/opt/airflow/dags/main.py", line 61, in api_url_request
    df.to_sql(name='raw_covid_data', con=mysql_engine, if_exists='replace', index=False)
  File "/home/airflow/.local/lib/python3.7/site-packages/pandas/core/generic.py", line 2882, in to_sql
    method=method,
  File "/home/airflow/.local/lib/python3.7/site-packages/pandas/io/sql.py", line 728, in to_sql
    **engine_kwargs,
  File "/home/airflow/.local/lib/python3.7/site-packages/pandas/io/sql.py", line 1758, in to_sql
    dtype=dtype,
  File "/home/airflow/.local/lib/python3.7/site-packages/pandas/io/sql.py", line 1650, in prep_table
    table.create()
  File "/home/airflow/.local/lib/python3.7/site-packages/pandas/io/sql.py", line 860, in create
    self.pd_sql.drop_table(self.name, self.schema)
  File "/home/airflow/.local/lib/python3.7/site-packages/pandas/io/sql.py", line 1810, in drop_table
    self.get_table(table_name, schema).drop()
  File "/home/airflow/.local/lib/python3.7/site-packages/sqlalchemy/sql/schema.py", line 960, in drop
    bind._run_ddl_visitor(ddl.SchemaDropper, self, checkfirst=checkfirst)
  File "/home/airflow/.local/lib/python3.7/site-packages/sqlalchemy/engine/base.py", line 3008, in _run_ddl_visitor
    conn._run_ddl_visitor(visitorcallable, element, **kwargs)
  File "/home/airflow/.local/lib/python3.7/site-packages/sqlalchemy/engine/base.py", line 2016, in _run_ddl_visitor
    visitorcallable(self.dialect, self, **kwargs).traverse_single(element)
  File "/home/airflow/.local/lib/python3.7/site-packages/sqlalchemy/sql/visitors.py", line 483, in traverse_single
    return meth(obj, **kw)
  File "/home/airflow/.local/lib/python3.7/site-packages/sqlalchemy/sql/ddl.py", line 1097, in visit_table
    self.connection.execute(DropTable(table))
  File "/home/airflow/.local/lib/python3.7/site-packages/sqlalchemy/engine/base.py", line 1200, in execute
    return meth(self, multiparams, params, _EMPTY_EXECUTION_OPTS)
  File "/home/airflow/.local/lib/python3.7/site-packages/sqlalchemy/sql/ddl.py", line 78, in _execute_on_connection
    self, multiparams, params, execution_options
  File "/home/airflow/.local/lib/python3.7/site-packages/sqlalchemy/engine/base.py", line 1296, in _execute_ddl
    compiled,
  File "/home/airflow/.local/lib/python3.7/site-packages/sqlalchemy/engine/base.py", line 1749, in _execute_context
    e, statement, parameters, cursor, context
  File "/home/airflow/.local/lib/python3.7/site-packages/sqlalchemy/engine/base.py", line 1930, in _handle_dbapi_exception
    sqlalchemy_exception, with_traceback=exc_info[2], from_=e
  File "/home/airflow/.local/lib/python3.7/site-packages/sqlalchemy/util/compat.py", line 211, in raise_
    raise exception
  File "/home/airflow/.local/lib/python3.7/site-packages/sqlalchemy/engine/base.py", line 1706, in _execute_context
    cursor, statement, parameters, context
  File "/home/airflow/.local/lib/python3.7/site-packages/sqlalchemy/engine/default.py", line 716, in do_execute
    cursor.execute(statement, parameters)
  File "/home/airflow/.local/lib/python3.7/site-packages/mysql/connector/cursor_cext.py", line 271, in execute
    raw_as_string=self._raw_as_string)
  File "/home/airflow/.local/lib/python3.7/site-packages/mysql/connector/connection_cext.py", line 541, in cmd_query
    sqlstate=exc.sqlstate)
sqlalchemy.exc.ProgrammingError: (mysql.connector.errors.ProgrammingError) 1051 (42S02): Unknown table 'mysql-data-staging.raw_covid_data'
[SQL: 
DROP TABLE raw_covid_data]
(Background on this error at: http://sqlalche.me/e/14/f405)
[2024-01-31 15:38:06,121] {taskinstance.py:1400} INFO - Marking task as UP_FOR_RETRY. dag_id=project_6_9, task_id=api_url_request, execution_date=20240131T153801, start_date=20240131T153804, end_date=20240131T153806
[2024-01-31 15:38:06,161] {standard_task_runner.py:97} ERROR - Failed to execute job 113 for task api_url_request ((mysql.connector.errors.ProgrammingError) 1051 (42S02): Unknown table 'mysql-data-staging.raw_covid_data'
[SQL: 
DROP TABLE raw_covid_data]
(Background on this error at: http://sqlalche.me/e/14/f405); 7909)
[2024-01-31 15:38:06,198] {local_task_job.py:156} INFO - Task exited with return code 1
[2024-01-31 15:38:06,407] {local_task_job.py:273} INFO - 0 downstream tasks scheduled from follow-on schedule check
