[2024-01-31 10:33:33,981] {taskinstance.py:1159} INFO - Dependencies all met for <TaskInstance: database_connection_testing_mysql_postgres_5.postgres_conn_check scheduled__2024-01-30T10:33:28.354990+00:00 [queued]>
[2024-01-31 10:33:33,988] {taskinstance.py:1159} INFO - Dependencies all met for <TaskInstance: database_connection_testing_mysql_postgres_5.postgres_conn_check scheduled__2024-01-30T10:33:28.354990+00:00 [queued]>
[2024-01-31 10:33:33,988] {taskinstance.py:1356} INFO - 
--------------------------------------------------------------------------------
[2024-01-31 10:33:33,989] {taskinstance.py:1357} INFO - Starting attempt 1 of 2
[2024-01-31 10:33:33,989] {taskinstance.py:1358} INFO - 
--------------------------------------------------------------------------------
[2024-01-31 10:33:34,003] {taskinstance.py:1377} INFO - Executing <Task(PythonOperator): postgres_conn_check> on 2024-01-30 10:33:28.354990+00:00
[2024-01-31 10:33:34,006] {standard_task_runner.py:52} INFO - Started process 6749 to run task
[2024-01-31 10:33:34,009] {standard_task_runner.py:79} INFO - Running: ['***', 'tasks', 'run', 'database_connection_testing_mysql_postgres_5', 'postgres_conn_check', 'scheduled__2024-01-30T10:33:28.354990+00:00', '--job-id', '22', '--raw', '--subdir', 'DAGS_FOLDER/test_connection.py', '--cfg-path', '/tmp/tmp_r2o_ahu', '--error-file', '/tmp/tmp2aop2gt7']
[2024-01-31 10:33:34,010] {standard_task_runner.py:80} INFO - Job 22: Subtask postgres_conn_check
[2024-01-31 10:33:34,051] {task_command.py:369} INFO - Running <TaskInstance: database_connection_testing_mysql_postgres_5.postgres_conn_check scheduled__2024-01-30T10:33:28.354990+00:00 [running]> on host f72468368ef9
[2024-01-31 10:33:34,110] {taskinstance.py:1571} INFO - Exporting the following env vars:
AIRFLOW_CTX_DAG_OWNER=***
AIRFLOW_CTX_DAG_ID=database_connection_testing_mysql_postgres_5
AIRFLOW_CTX_TASK_ID=postgres_conn_check
AIRFLOW_CTX_EXECUTION_DATE=2024-01-30T10:33:28.354990+00:00
AIRFLOW_CTX_TRY_NUMBER=1
AIRFLOW_CTX_DAG_RUN_ID=scheduled__2024-01-30T10:33:28.354990+00:00
[2024-01-31 10:33:34,111] {logging_mixin.py:115} INFO - Error connecting to PostgreSQL: could not connect to server: Connection refused
	Is the server running on host "172.18.0.4" and accepting
	TCP/IP connections on port 5434?
[2024-01-31 10:33:34,111] {python.py:173} INFO - Done. Returned value was: False
[2024-01-31 10:33:34,129] {taskinstance.py:1400} INFO - Marking task as SUCCESS. dag_id=database_connection_testing_mysql_postgres_5, task_id=postgres_conn_check, execution_date=20240130T103328, start_date=20240131T103333, end_date=20240131T103334
[2024-01-31 10:33:34,142] {local_task_job.py:156} INFO - Task exited with return code 0
[2024-01-31 10:33:34,166] {local_task_job.py:273} INFO - 1 downstream tasks scheduled from follow-on schedule check
