[2024-01-31 10:33:33,961] {taskinstance.py:1159} INFO - Dependencies all met for <TaskInstance: database_connection_testing_mysql_postgres_5.mysql_conn_check scheduled__2024-01-30T10:33:28.354990+00:00 [queued]>
[2024-01-31 10:33:33,966] {taskinstance.py:1159} INFO - Dependencies all met for <TaskInstance: database_connection_testing_mysql_postgres_5.mysql_conn_check scheduled__2024-01-30T10:33:28.354990+00:00 [queued]>
[2024-01-31 10:33:33,967] {taskinstance.py:1356} INFO - 
--------------------------------------------------------------------------------
[2024-01-31 10:33:33,967] {taskinstance.py:1357} INFO - Starting attempt 1 of 2
[2024-01-31 10:33:33,967] {taskinstance.py:1358} INFO - 
--------------------------------------------------------------------------------
[2024-01-31 10:33:33,975] {taskinstance.py:1377} INFO - Executing <Task(PythonOperator): mysql_conn_check> on 2024-01-30 10:33:28.354990+00:00
[2024-01-31 10:33:33,978] {standard_task_runner.py:52} INFO - Started process 6748 to run task
[2024-01-31 10:33:33,980] {standard_task_runner.py:79} INFO - Running: ['***', 'tasks', 'run', 'database_connection_testing_mysql_postgres_5', 'mysql_conn_check', 'scheduled__2024-01-30T10:33:28.354990+00:00', '--job-id', '23', '--raw', '--subdir', 'DAGS_FOLDER/test_connection.py', '--cfg-path', '/tmp/tmp0ee1ndnp', '--error-file', '/tmp/tmpcd_ggl5u']
[2024-01-31 10:33:33,981] {standard_task_runner.py:80} INFO - Job 23: Subtask mysql_conn_check
[2024-01-31 10:33:34,035] {task_command.py:369} INFO - Running <TaskInstance: database_connection_testing_mysql_postgres_5.mysql_conn_check scheduled__2024-01-30T10:33:28.354990+00:00 [running]> on host f72468368ef9
[2024-01-31 10:33:34,098] {taskinstance.py:1571} INFO - Exporting the following env vars:
AIRFLOW_CTX_DAG_OWNER=***
AIRFLOW_CTX_DAG_ID=database_connection_testing_mysql_postgres_5
AIRFLOW_CTX_TASK_ID=mysql_conn_check
AIRFLOW_CTX_EXECUTION_DATE=2024-01-30T10:33:28.354990+00:00
AIRFLOW_CTX_TRY_NUMBER=1
AIRFLOW_CTX_DAG_RUN_ID=scheduled__2024-01-30T10:33:28.354990+00:00
[2024-01-31 10:33:34,099] {logging_mixin.py:115} INFO - Error connecting to MySQL: No module named 'mysql'
[2024-01-31 10:33:34,100] {python.py:173} INFO - Done. Returned value was: False
[2024-01-31 10:33:34,118] {taskinstance.py:1400} INFO - Marking task as SUCCESS. dag_id=database_connection_testing_mysql_postgres_5, task_id=mysql_conn_check, execution_date=20240130T103328, start_date=20240131T103333, end_date=20240131T103334
[2024-01-31 10:33:34,154] {local_task_job.py:156} INFO - Task exited with return code 0
[2024-01-31 10:33:34,175] {local_task_job.py:273} INFO - 0 downstream tasks scheduled from follow-on schedule check
