[2024-01-31 15:38:32,477] {taskinstance.py:1159} INFO - Dependencies all met for <TaskInstance: project_6_9.dim_prov manual__2024-01-31T15:38:01.809045+00:00 [queued]>
[2024-01-31 15:38:32,490] {taskinstance.py:1159} INFO - Dependencies all met for <TaskInstance: project_6_9.dim_prov manual__2024-01-31T15:38:01.809045+00:00 [queued]>
[2024-01-31 15:38:32,490] {taskinstance.py:1356} INFO - 
--------------------------------------------------------------------------------
[2024-01-31 15:38:32,490] {taskinstance.py:1357} INFO - Starting attempt 2 of 2
[2024-01-31 15:38:32,491] {taskinstance.py:1358} INFO - 
--------------------------------------------------------------------------------
[2024-01-31 15:38:32,515] {taskinstance.py:1377} INFO - Executing <Task(PostgresOperator): dim_prov> on 2024-01-31 15:38:01.809045+00:00
[2024-01-31 15:38:32,523] {standard_task_runner.py:52} INFO - Started process 7941 to run task
[2024-01-31 15:38:32,528] {standard_task_runner.py:79} INFO - Running: ['***', 'tasks', 'run', 'project_6_9', 'dim_prov', 'manual__2024-01-31T15:38:01.809045+00:00', '--job-id', '118', '--raw', '--subdir', 'DAGS_FOLDER/main.py', '--cfg-path', '/tmp/tmpzkb2hfvp', '--error-file', '/tmp/tmps0gc2o82']
[2024-01-31 15:38:32,529] {standard_task_runner.py:80} INFO - Job 118: Subtask dim_prov
[2024-01-31 15:38:32,710] {task_command.py:369} INFO - Running <TaskInstance: project_6_9.dim_prov manual__2024-01-31T15:38:01.809045+00:00 [running]> on host 8ebb6ccf62d7
[2024-01-31 15:38:32,798] {taskinstance.py:1889} ERROR - Task failed with exception
Traceback (most recent call last):
  File "/home/airflow/.local/lib/python3.7/site-packages/airflow/models/taskinstance.py", line 1451, in _run_raw_task
    self._execute_task_with_callbacks(context, test_mode)
  File "/home/airflow/.local/lib/python3.7/site-packages/airflow/models/taskinstance.py", line 1555, in _execute_task_with_callbacks
    task_orig = self.render_templates(context=context)
  File "/home/airflow/.local/lib/python3.7/site-packages/airflow/models/taskinstance.py", line 2202, in render_templates
    rendered_task = self.task.render_template_fields(context)
  File "/home/airflow/.local/lib/python3.7/site-packages/airflow/models/baseoperator.py", line 1179, in render_template_fields
    self._do_render_template_fields(self, self.template_fields, context, jinja_env, set())
  File "/home/airflow/.local/lib/python3.7/site-packages/airflow/utils/session.py", line 71, in wrapper
    return func(*args, session=session, **kwargs)
  File "/home/airflow/.local/lib/python3.7/site-packages/airflow/models/abstractoperator.py", line 348, in _do_render_template_fields
    seen_oids,
  File "/home/airflow/.local/lib/python3.7/site-packages/airflow/models/abstractoperator.py", line 385, in render_template
    template = jinja_env.get_template(value)
  File "/home/airflow/.local/lib/python3.7/site-packages/jinja2/environment.py", line 997, in get_template
    return self._load_template(name, globals)
  File "/home/airflow/.local/lib/python3.7/site-packages/jinja2/environment.py", line 958, in _load_template
    template = self.loader.load(self, name, self.make_globals(globals))
  File "/home/airflow/.local/lib/python3.7/site-packages/jinja2/loaders.py", line 125, in load
    source, filename, uptodate = self.get_source(environment, name)
  File "/home/airflow/.local/lib/python3.7/site-packages/jinja2/loaders.py", line 214, in get_source
    raise TemplateNotFound(template)
jinja2.exceptions.TemplateNotFound: dags/sql/raw_ddl.sql
[2024-01-31 15:38:32,851] {taskinstance.py:1400} INFO - Marking task as FAILED. dag_id=project_6_9, task_id=dim_prov, execution_date=20240131T153801, start_date=20240131T153832, end_date=20240131T153832
[2024-01-31 15:38:32,877] {standard_task_runner.py:97} ERROR - Failed to execute job 118 for task dim_prov (dags/sql/raw_ddl.sql; 7941)
[2024-01-31 15:38:32,907] {local_task_job.py:156} INFO - Task exited with return code 1
[2024-01-31 15:38:33,060] {local_task_job.py:273} INFO - 0 downstream tasks scheduled from follow-on schedule check
