[2024-01-31 15:38:07,517] {taskinstance.py:1159} INFO - Dependencies all met for <TaskInstance: project_6_9.dim_prov scheduled__2024-01-30T15:37:55.232349+00:00 [queued]>
[2024-01-31 15:38:07,531] {taskinstance.py:1159} INFO - Dependencies all met for <TaskInstance: project_6_9.dim_prov scheduled__2024-01-30T15:37:55.232349+00:00 [queued]>
[2024-01-31 15:38:07,531] {taskinstance.py:1356} INFO - 
--------------------------------------------------------------------------------
[2024-01-31 15:38:07,532] {taskinstance.py:1357} INFO - Starting attempt 1 of 2
[2024-01-31 15:38:07,532] {taskinstance.py:1358} INFO - 
--------------------------------------------------------------------------------
[2024-01-31 15:38:07,557] {taskinstance.py:1377} INFO - Executing <Task(PostgresOperator): dim_prov> on 2024-01-30 15:37:55.232349+00:00
[2024-01-31 15:38:07,567] {standard_task_runner.py:52} INFO - Started process 7912 to run task
[2024-01-31 15:38:07,571] {standard_task_runner.py:79} INFO - Running: ['***', 'tasks', 'run', 'project_6_9', 'dim_prov', 'scheduled__2024-01-30T15:37:55.232349+00:00', '--job-id', '114', '--raw', '--subdir', 'DAGS_FOLDER/main.py', '--cfg-path', '/tmp/tmpn0r5smq7', '--error-file', '/tmp/tmptca7uram']
[2024-01-31 15:38:07,572] {standard_task_runner.py:80} INFO - Job 114: Subtask dim_prov
[2024-01-31 15:38:07,763] {task_command.py:369} INFO - Running <TaskInstance: project_6_9.dim_prov scheduled__2024-01-30T15:37:55.232349+00:00 [running]> on host 8ebb6ccf62d7
[2024-01-31 15:38:07,848] {taskinstance.py:1889} ERROR - Task failed with exception
Traceback (most recent call last):
  File "/home/airflow/.local/lib/python3.7/site-packages/airflow/models/taskinstance.py", line 1451, in _run_raw_task
    self._execute_task_with_callbacks(context, test_mode)
  File "/home/airflow/.local/lib/python3.7/site-packages/airflow/models/taskinstance.py", line 1555, in _execute_task_with_callbacks
    task_orig = self.render_templates(context=context)
  File "/home/airflow/.local/lib/python3.7/site-packages/airflow/models/taskinstance.py", line 2202, in render_templates
    rendered_task = self.task.render_template_fields(context)
  File "/home/airflow/.local/lib/python3.7/site-packages/airflow/models/baseoperator.py", line 1179, in render_template_fields
    self._do_render_template_fields(self, self.template_fields, context, jinja_env, set())
  File "/home/airflow/.local/lib/python3.7/site-packages/airflow/utils/session.py", line 71, in wrapper
    return func(*args, session=session, **kwargs)
  File "/home/airflow/.local/lib/python3.7/site-packages/airflow/models/abstractoperator.py", line 348, in _do_render_template_fields
    seen_oids,
  File "/home/airflow/.local/lib/python3.7/site-packages/airflow/models/abstractoperator.py", line 385, in render_template
    template = jinja_env.get_template(value)
  File "/home/airflow/.local/lib/python3.7/site-packages/jinja2/environment.py", line 997, in get_template
    return self._load_template(name, globals)
  File "/home/airflow/.local/lib/python3.7/site-packages/jinja2/environment.py", line 958, in _load_template
    template = self.loader.load(self, name, self.make_globals(globals))
  File "/home/airflow/.local/lib/python3.7/site-packages/jinja2/loaders.py", line 125, in load
    source, filename, uptodate = self.get_source(environment, name)
  File "/home/airflow/.local/lib/python3.7/site-packages/jinja2/loaders.py", line 214, in get_source
    raise TemplateNotFound(template)
jinja2.exceptions.TemplateNotFound: dags/sql/raw_ddl.sql
[2024-01-31 15:38:07,905] {taskinstance.py:1400} INFO - Marking task as UP_FOR_RETRY. dag_id=project_6_9, task_id=dim_prov, execution_date=20240130T153755, start_date=20240131T153807, end_date=20240131T153807
[2024-01-31 15:38:07,932] {standard_task_runner.py:97} ERROR - Failed to execute job 114 for task dim_prov (dags/sql/raw_ddl.sql; 7912)
[2024-01-31 15:38:07,946] {local_task_job.py:156} INFO - Task exited with return code 1
[2024-01-31 15:38:08,088] {local_task_job.py:273} INFO - 0 downstream tasks scheduled from follow-on schedule check
