[2024-02-01 15:30:55,404] {taskinstance.py:1159} INFO - Dependencies all met for <TaskInstance: project_6_15.insert_data_dim_table scheduled__2024-01-31T15:30:21.392570+00:00 [queued]>
[2024-02-01 15:30:55,459] {taskinstance.py:1159} INFO - Dependencies all met for <TaskInstance: project_6_15.insert_data_dim_table scheduled__2024-01-31T15:30:21.392570+00:00 [queued]>
[2024-02-01 15:30:55,460] {taskinstance.py:1356} INFO - 
--------------------------------------------------------------------------------
[2024-02-01 15:30:55,461] {taskinstance.py:1357} INFO - Starting attempt 2 of 2
[2024-02-01 15:30:55,461] {taskinstance.py:1358} INFO - 
--------------------------------------------------------------------------------
[2024-02-01 15:30:55,524] {taskinstance.py:1377} INFO - Executing <Task(PythonOperator): insert_data_dim_table> on 2024-01-31 15:30:21.392570+00:00
[2024-02-01 15:30:55,558] {standard_task_runner.py:52} INFO - Started process 5135 to run task
[2024-02-01 15:30:55,567] {standard_task_runner.py:79} INFO - Running: ['***', 'tasks', 'run', 'project_6_15', 'insert_data_dim_table', 'scheduled__2024-01-31T15:30:21.392570+00:00', '--job-id', '215', '--raw', '--subdir', 'DAGS_FOLDER/main.py', '--cfg-path', '/tmp/tmps20kgqgu', '--error-file', '/tmp/tmp48lj6ekl']
[2024-02-01 15:30:55,569] {standard_task_runner.py:80} INFO - Job 215: Subtask insert_data_dim_table
[2024-02-01 15:30:55,781] {task_command.py:369} INFO - Running <TaskInstance: project_6_15.insert_data_dim_table scheduled__2024-01-31T15:30:21.392570+00:00 [running]> on host 1fafaef2f352
[2024-02-01 15:30:56,011] {taskinstance.py:1571} INFO - Exporting the following env vars:
AIRFLOW_CTX_DAG_OWNER=***
AIRFLOW_CTX_DAG_ID=project_6_15
AIRFLOW_CTX_TASK_ID=insert_data_dim_table
AIRFLOW_CTX_EXECUTION_DATE=2024-01-31T15:30:21.392570+00:00
AIRFLOW_CTX_TRY_NUMBER=2
AIRFLOW_CTX_DAG_RUN_ID=scheduled__2024-01-31T15:30:21.392570+00:00
[2024-02-01 15:30:56,047] {taskinstance.py:1889} ERROR - Task failed with exception
Traceback (most recent call last):
  File "/home/airflow/.local/lib/python3.7/site-packages/airflow/operators/python.py", line 171, in execute
    return_value = self.execute_callable()
  File "/home/airflow/.local/lib/python3.7/site-packages/airflow/operators/python.py", line 189, in execute_callable
    return self.python_callable(*self.op_args, **self.op_kwargs)
  File "/opt/airflow/dags/main.py", line 113, in insert_data_dim_table
    df = pd.read_csv('data raw.csv')
  File "/home/airflow/.local/lib/python3.7/site-packages/pandas/util/_decorators.py", line 311, in wrapper
    return func(*args, **kwargs)
  File "/home/airflow/.local/lib/python3.7/site-packages/pandas/io/parsers/readers.py", line 586, in read_csv
    return _read(filepath_or_buffer, kwds)
  File "/home/airflow/.local/lib/python3.7/site-packages/pandas/io/parsers/readers.py", line 482, in _read
    parser = TextFileReader(filepath_or_buffer, **kwds)
  File "/home/airflow/.local/lib/python3.7/site-packages/pandas/io/parsers/readers.py", line 811, in __init__
    self._engine = self._make_engine(self.engine)
  File "/home/airflow/.local/lib/python3.7/site-packages/pandas/io/parsers/readers.py", line 1040, in _make_engine
    return mapping[engine](self.f, **self.options)  # type: ignore[call-arg]
  File "/home/airflow/.local/lib/python3.7/site-packages/pandas/io/parsers/c_parser_wrapper.py", line 51, in __init__
    self._open_handles(src, kwds)
  File "/home/airflow/.local/lib/python3.7/site-packages/pandas/io/parsers/base_parser.py", line 229, in _open_handles
    errors=kwds.get("encoding_errors", "strict"),
  File "/home/airflow/.local/lib/python3.7/site-packages/pandas/io/common.py", line 707, in get_handle
    newline="",
FileNotFoundError: [Errno 2] No such file or directory: 'data raw.csv'
[2024-02-01 15:30:56,103] {taskinstance.py:1400} INFO - Marking task as FAILED. dag_id=project_6_15, task_id=insert_data_dim_table, execution_date=20240131T153021, start_date=20240201T153055, end_date=20240201T153056
[2024-02-01 15:30:56,130] {standard_task_runner.py:97} ERROR - Failed to execute job 215 for task insert_data_dim_table ([Errno 2] No such file or directory: 'data raw.csv'; 5135)
[2024-02-01 15:30:56,155] {local_task_job.py:156} INFO - Task exited with return code 1
[2024-02-01 15:30:56,294] {local_task_job.py:273} INFO - 0 downstream tasks scheduled from follow-on schedule check
