[2024-02-02 08:21:53,946] {taskinstance.py:1159} INFO - Dependencies all met for <TaskInstance: project_6_30.aggregation_prov manual__2024-02-02T08:21:42.184126+00:00 [queued]>
[2024-02-02 08:21:53,958] {taskinstance.py:1159} INFO - Dependencies all met for <TaskInstance: project_6_30.aggregation_prov manual__2024-02-02T08:21:42.184126+00:00 [queued]>
[2024-02-02 08:21:53,958] {taskinstance.py:1356} INFO - 
--------------------------------------------------------------------------------
[2024-02-02 08:21:53,958] {taskinstance.py:1357} INFO - Starting attempt 1 of 2
[2024-02-02 08:21:53,958] {taskinstance.py:1358} INFO - 
--------------------------------------------------------------------------------
[2024-02-02 08:21:53,979] {taskinstance.py:1377} INFO - Executing <Task(PythonOperator): aggregation_prov> on 2024-02-02 08:21:42.184126+00:00
[2024-02-02 08:21:53,987] {standard_task_runner.py:52} INFO - Started process 8931 to run task
[2024-02-02 08:21:53,991] {standard_task_runner.py:79} INFO - Running: ['***', 'tasks', 'run', 'project_6_30', 'aggregation_prov', 'manual__2024-02-02T08:21:42.184126+00:00', '--job-id', '494', '--raw', '--subdir', 'DAGS_FOLDER/main.py', '--cfg-path', '/tmp/tmpp5qrg4up', '--error-file', '/tmp/tmp0ttz9e3k']
[2024-02-02 08:21:53,992] {standard_task_runner.py:80} INFO - Job 494: Subtask aggregation_prov
[2024-02-02 08:21:54,231] {task_command.py:369} INFO - Running <TaskInstance: project_6_30.aggregation_prov manual__2024-02-02T08:21:42.184126+00:00 [running]> on host 20775c919683
[2024-02-02 08:21:54,504] {taskinstance.py:1571} INFO - Exporting the following env vars:
AIRFLOW_CTX_DAG_OWNER=***
AIRFLOW_CTX_DAG_ID=project_6_30
AIRFLOW_CTX_TASK_ID=aggregation_prov
AIRFLOW_CTX_EXECUTION_DATE=2024-02-02T08:21:42.184126+00:00
AIRFLOW_CTX_TRY_NUMBER=1
AIRFLOW_CTX_DAG_RUN_ID=manual__2024-02-02T08:21:42.184126+00:00
[2024-02-02 08:21:54,644] {logging_mixin.py:115} INFO -    id  kode_prov  case_id     tanggal  total
0   1         32        1  2020-08-05   1815
[2024-02-02 08:21:54,660] {logging_mixin.py:115} INFO -    id  kode_prov  case_id year_month  total
0   1         32        1    2020-08   2507
[2024-02-02 08:21:54,674] {logging_mixin.py:115} INFO -    kode_prov  id  case_id  year  total
0         32  10        1  2020   2507
[2024-02-02 08:21:54,704] {logging_mixin.py:115} INFO - Connect PostgreSQL using psycopg2
[2024-02-02 08:21:54,704] {taskinstance.py:1889} ERROR - Task failed with exception
Traceback (most recent call last):
  File "/home/airflow/.local/lib/python3.7/site-packages/airflow/operators/python.py", line 171, in execute
    return_value = self.execute_callable()
  File "/home/airflow/.local/lib/python3.7/site-packages/airflow/operators/python.py", line 189, in execute_callable
    return self.python_callable(*self.op_args, **self.op_kwargs)
  File "/opt/airflow/dags/main.py", line 209, in aggregation_prov
    insert_into_postgres(conn_postgres, 'daily_province', df_harian_merge, debug=True)
TypeError: insert_into_postgres() got an unexpected keyword argument 'debug'
[2024-02-02 08:21:54,761] {taskinstance.py:1400} INFO - Marking task as UP_FOR_RETRY. dag_id=project_6_30, task_id=aggregation_prov, execution_date=20240202T082142, start_date=20240202T082153, end_date=20240202T082154
[2024-02-02 08:21:54,796] {standard_task_runner.py:97} ERROR - Failed to execute job 494 for task aggregation_prov (insert_into_postgres() got an unexpected keyword argument 'debug'; 8931)
[2024-02-02 08:21:54,817] {local_task_job.py:156} INFO - Task exited with return code 1
[2024-02-02 08:21:54,956] {local_task_job.py:273} INFO - 0 downstream tasks scheduled from follow-on schedule check
