[2024-02-02 08:22:06,010] {taskinstance.py:1159} INFO - Dependencies all met for <TaskInstance: project_6_30.aggregation_prov manual__2024-02-02T08:21:42.184126+00:00 [queued]>
[2024-02-02 08:22:06,049] {taskinstance.py:1159} INFO - Dependencies all met for <TaskInstance: project_6_30.aggregation_prov manual__2024-02-02T08:21:42.184126+00:00 [queued]>
[2024-02-02 08:22:06,050] {taskinstance.py:1356} INFO - 
--------------------------------------------------------------------------------
[2024-02-02 08:22:06,050] {taskinstance.py:1357} INFO - Starting attempt 2 of 2
[2024-02-02 08:22:06,051] {taskinstance.py:1358} INFO - 
--------------------------------------------------------------------------------
[2024-02-02 08:22:06,105] {taskinstance.py:1377} INFO - Executing <Task(PythonOperator): aggregation_prov> on 2024-02-02 08:21:42.184126+00:00
[2024-02-02 08:22:06,120] {standard_task_runner.py:52} INFO - Started process 8968 to run task
[2024-02-02 08:22:06,125] {standard_task_runner.py:79} INFO - Running: ['***', 'tasks', 'run', 'project_6_30', 'aggregation_prov', 'manual__2024-02-02T08:21:42.184126+00:00', '--job-id', '501', '--raw', '--subdir', 'DAGS_FOLDER/main.py', '--cfg-path', '/tmp/tmpnjmrfogh', '--error-file', '/tmp/tmp5wfkc9h5']
[2024-02-02 08:22:06,126] {standard_task_runner.py:80} INFO - Job 501: Subtask aggregation_prov
[2024-02-02 08:22:06,451] {task_command.py:369} INFO - Running <TaskInstance: project_6_30.aggregation_prov manual__2024-02-02T08:21:42.184126+00:00 [running]> on host 20775c919683
[2024-02-02 08:22:06,789] {taskinstance.py:1571} INFO - Exporting the following env vars:
AIRFLOW_CTX_DAG_OWNER=***
AIRFLOW_CTX_DAG_ID=project_6_30
AIRFLOW_CTX_TASK_ID=aggregation_prov
AIRFLOW_CTX_EXECUTION_DATE=2024-02-02T08:21:42.184126+00:00
AIRFLOW_CTX_TRY_NUMBER=2
AIRFLOW_CTX_DAG_RUN_ID=manual__2024-02-02T08:21:42.184126+00:00
[2024-02-02 08:22:07,011] {logging_mixin.py:115} INFO -    id  kode_prov  case_id     tanggal  total
0   1         32        1  2020-08-05   1815
[2024-02-02 08:22:07,036] {logging_mixin.py:115} INFO -    id  kode_prov  case_id year_month  total
0   1         32        1    2020-08   2507
[2024-02-02 08:22:07,068] {logging_mixin.py:115} INFO -    kode_prov  id  case_id  year  total
0         32  10        1  2020   2507
[2024-02-02 08:22:07,148] {logging_mixin.py:115} INFO - Connect PostgreSQL using psycopg2
[2024-02-02 08:22:07,149] {taskinstance.py:1889} ERROR - Task failed with exception
Traceback (most recent call last):
  File "/home/airflow/.local/lib/python3.7/site-packages/airflow/operators/python.py", line 171, in execute
    return_value = self.execute_callable()
  File "/home/airflow/.local/lib/python3.7/site-packages/airflow/operators/python.py", line 189, in execute_callable
    return self.python_callable(*self.op_args, **self.op_kwargs)
  File "/opt/airflow/dags/main.py", line 209, in aggregation_prov
    insert_into_postgres(conn_postgres, 'daily_province', df_harian_merge, debug=True)
TypeError: insert_into_postgres() got an unexpected keyword argument 'debug'
[2024-02-02 08:22:07,387] {taskinstance.py:1400} INFO - Marking task as FAILED. dag_id=project_6_30, task_id=aggregation_prov, execution_date=20240202T082142, start_date=20240202T082206, end_date=20240202T082207
[2024-02-02 08:22:07,453] {standard_task_runner.py:97} ERROR - Failed to execute job 501 for task aggregation_prov (insert_into_postgres() got an unexpected keyword argument 'debug'; 8968)
[2024-02-02 08:22:07,475] {local_task_job.py:156} INFO - Task exited with return code 1
[2024-02-02 08:22:07,686] {local_task_job.py:273} INFO - 0 downstream tasks scheduled from follow-on schedule check
