[2024-01-31 13:53:58,528] {taskinstance.py:1159} INFO - Dependencies all met for <TaskInstance: project_6_5.create_table manual__2024-01-31T13:50:27.684979+00:00 [queued]>
[2024-01-31 13:53:58,560] {taskinstance.py:1159} INFO - Dependencies all met for <TaskInstance: project_6_5.create_table manual__2024-01-31T13:50:27.684979+00:00 [queued]>
[2024-01-31 13:53:58,561] {taskinstance.py:1356} INFO - 
--------------------------------------------------------------------------------
[2024-01-31 13:53:58,561] {taskinstance.py:1357} INFO - Starting attempt 3 of 4
[2024-01-31 13:53:58,561] {taskinstance.py:1358} INFO - 
--------------------------------------------------------------------------------
[2024-01-31 13:53:58,604] {taskinstance.py:1377} INFO - Executing <Task(MySqlOperator): create_table> on 2024-01-31 13:50:27.684979+00:00
[2024-01-31 13:53:58,620] {standard_task_runner.py:52} INFO - Started process 4444 to run task
[2024-01-31 13:53:58,629] {standard_task_runner.py:79} INFO - Running: ['***', 'tasks', 'run', 'project_6_5', 'create_table', 'manual__2024-01-31T13:50:27.684979+00:00', '--job-id', '95', '--raw', '--subdir', 'DAGS_FOLDER/main.py', '--cfg-path', '/tmp/tmpg6ec_qze', '--error-file', '/tmp/tmp8jz7athm']
[2024-01-31 13:53:58,631] {standard_task_runner.py:80} INFO - Job 95: Subtask create_table
[2024-01-31 13:53:59,037] {task_command.py:369} INFO - Running <TaskInstance: project_6_5.create_table manual__2024-01-31T13:50:27.684979+00:00 [running]> on host 8ebb6ccf62d7
[2024-01-31 13:54:00,073] {taskinstance.py:1571} INFO - Exporting the following env vars:
AIRFLOW_CTX_DAG_OWNER=***
AIRFLOW_CTX_DAG_ID=project_6_5
AIRFLOW_CTX_TASK_ID=create_table
AIRFLOW_CTX_EXECUTION_DATE=2024-01-31T13:50:27.684979+00:00
AIRFLOW_CTX_TRY_NUMBER=3
AIRFLOW_CTX_DAG_RUN_ID=manual__2024-01-31T13:50:27.684979+00:00
[2024-01-31 13:54:00,077] {mysql.py:82} INFO - Executing: 
            CREATE TABLE IF NOT EXISTS test_1 (
                dt DATE,
                dag_id VARCHAR(255)
            )
        
[2024-01-31 13:54:00,176] {base.py:68} INFO - Using connection ID 'mysql_data_staging' for task execution.
[2024-01-31 13:54:00,266] {taskinstance.py:1889} ERROR - Task failed with exception
Traceback (most recent call last):
  File "/home/airflow/.local/lib/python3.7/site-packages/airflow/providers/mysql/operators/mysql.py", line 84, in execute
    hook.run(self.sql, autocommit=self.autocommit, parameters=self.parameters)
  File "/home/airflow/.local/lib/python3.7/site-packages/airflow/hooks/dbapi.py", line 181, in run
    with closing(self.get_conn()) as conn:
  File "/home/airflow/.local/lib/python3.7/site-packages/airflow/providers/mysql/hooks/mysql.py", line 166, in get_conn
    return MySQLdb.connect(**conn_config)
  File "/home/airflow/.local/lib/python3.7/site-packages/MySQLdb/__init__.py", line 123, in Connect
    return Connection(*args, **kwargs)
  File "/home/airflow/.local/lib/python3.7/site-packages/MySQLdb/connections.py", line 185, in __init__
    super().__init__(*args, **kwargs2)
MySQLdb._exceptions.OperationalError: (2003, "Can't connect to MySQL server on 'mysql-db:3307' (111)")
[2024-01-31 13:54:00,400] {taskinstance.py:1400} INFO - Marking task as UP_FOR_RETRY. dag_id=project_6_5, task_id=create_table, execution_date=20240131T135027, start_date=20240131T135358, end_date=20240131T135400
[2024-01-31 13:54:00,487] {standard_task_runner.py:97} ERROR - Failed to execute job 95 for task create_table ((2003, "Can't connect to MySQL server on 'mysql-db:3307' (111)"); 4444)
[2024-01-31 13:54:00,543] {local_task_job.py:156} INFO - Task exited with return code 1
[2024-01-31 13:54:00,997] {local_task_job.py:273} INFO - 0 downstream tasks scheduled from follow-on schedule check
